import AppError from '../../errors/appError.js';
import userService from '../../services/userService.js';
import { catchAsync } from '../../utils/index.js';

const isEmailUnique = catchAsync(async (req, res, next) => {
    const user = await userService.getUserByEmail(req.body.email);
    if (user) {
        return next(new AppError('email already exists', 409)); //409:conflict
    }
    return res.status(200).send({ status: 'success' });
});

const isUsernameUnique = catchAsync(async (req, res, next) => {
    const user = await userService.getUserByUsername(req.body.username);
    if (user) {
        return next(new AppError('username already exists', 409)); //409:conflict
    }
    return res.status(200).send({ status: 'success' });
});

const doesUUIDExits = catchAsync(async (req, res, next) => {
    const UUID = req.body.UUID;
    const user = await userService.getUserBasicInfoByUUID(UUID);
    if (!user) {
        return next(new AppError('no user found ', 404));
    }
    return res.status(200).send({ status: 'success' });
});

const checkPasswordController = catchAsync(async (req, res, next) => {
    return res.status(200).send({ status: 'success' });
});

export {
    isEmailUnique,
    isUsernameUnique,
    doesUUIDExits,
    checkPasswordController,
};
